# Promise

## 1.针对 Promise 对象内部的错误不会冒泡到全局这句话的理解

-   首先这句话出自于附加方法 done()函数的解释
-   done() 的作用是为了防止在链式调用的最后报错而出现的，因为不管最后是 then()还是 catch() 都有可能抛出错误，而这个错误无法捕获
-   其次，针对错误冒泡到全局这句话的理解：Promise 内部的错误只能通过 catch()捕获，假如没有出错了，但是没有 catch 捕获，虽然浏览器会打印报错，但是不会终止脚本的执行。
-   关于冒泡性质：Promise 对象的错误会一直向后传递，直到被捕获为止，也就是说错误总是会被下一个 catch 语句捕获
-   关于捕获错误：Promise 的状态一旦改变，就会永远保持该状态，不会再改变，因此相同作用域 resolve 之后的抛错不会被捕获

## 2.Promise.resolve() 返回的是一个状态为 resolved 的 Promise 对象
